Workbook

Sheet Equations
A1: Text Functions | D1: Aggregation Functions
A2: LEFT(text, [num_chars]) | B2: ترجع عدد معين من الحروف من بداية النص (من الشمال). | D2: SUM() | E2: تجمع كل الأرقام داخل نطاق
A3: RIGHT(text, [num_chars]) | B3: ترجع عدد معين من الحروف من نهاية النص (من اليمين) | D3: SUMIF | E3: تستخدم لما يكون عندك شرط واحد فقط.
A4: MID(text, start_num, num_chars) | B4: ترجع جزء من النص من منتصفه (من حرف معين). | D4: SUMIFS | E4: تستخدم لما يكون عندك أكثر من شرط (2 أو أكثر).
A5: LEN(text) | B5: تحسب عدد الحروف داخل النص | D5: COUNT | E5: تحسب عدد الخلايا اللي فيها أرقام فقط.
A6: FIND(find_text, within_text, [start_num]) | B6: تدور على مكان حرف أو كلمة معينة داخل النص (Case Sensitive) | D6: COUNTA | E6: تحسب عدد الخلايا الغير فاضية (حتى لو فيها نص).
A7: SEARCH(find_text, within_text, [start_num]) | B7: نفس فكرة FIND، بس مش حساسة لحالة الحروف (Case-insensitive) | D7: COUNTBLANK | E7: تحسب عدد الخلايا الفاضية
A8: UPPER(text) | B8: تحول كل الحروف إلى Capital (كبيرة). | D8: COUNTIF | E8: بتعدّ عدد الخلايا اللي تحقق شرط واحد.
A9: LOWER(text) | B9: تحول كل الحروف إلى Small (صغيرة) | D9: COUNTIFS | E9: بتعدّ الخلايا اللي تحقق أكتر من شرط.
A10: PROPER(text | B10: أول حرف من كل كلمة يكون Capital والباقي Small | D10: AVERAGE | E10: تحسب المتوسط الحسابي للقيم.
A11: TRIM(text) | B11: يشيل أي مسافات زيادة في النص (ماعدا مسافة واحدة بين الكلمات) | D11: AVERAGEIF | E11: بتحسب المتوسط بناءً على شرط واحد.
A12: TEXTJOIN(delimiter, ignore_empty, text1, [text2], …) | B12: تربط النصوص باستخدام فاصل معين (زي مسافة، فاصلة...) | D12: AVERAGEIFS | E12: بتحسب المتوسط بناءً على أكثر من شرط.
A13: SUBSTITUTE(text, old_text, new_text, [instance_num]) | B13: تستبدل كلمة أو حرف معين في النص (مش حسب المكان، بل حسب القيمة). | D13: MAX | E13: ترجع أكبر رقم في النطاق
D14: MIN | E14: ترجع أصغر رقم في النطاق.
A15: Statistical Functions
A16: AVERAGE(range) | B16: يحسب المتوسط الحسابي.
A17: MEDIAN(range) | B17: يجيب القيمة اللي في منتصف البيانات بعد الترتيب.
A18: MODE.SNGL(range) | B18: أكثر قيمة مكررة في البيانات.
A19: MAX(range)-MIN(range) | B19: الفرق بين أكبر وأصغر قيمة.
A20: MAX(range) | B20: أكبر قيمة.
A21: MIN(range) | B21: أصغر قيمة.
A22: STDEV.S(range) | B22: يقيس مدى تشتت القيم لعينة.
A23: VAR.S(range) | B23: مقياس تشتت القيم لعينة.
A24: MAX
A25: MIN

Sheet Row_Data
A1: Order ID | B1: Date | C1: Customer Email | D1: Product | E1: Category | F1: Quantity | G1: Unit Price | H1: Payment Method | I1: Status | J1: City | K1: Total_Sales | L1: Month
A2: 2660 | B2: 45664 | C2: espinozamaria@lewis.com | D2: Laptop | E2: Accessories | F2: 4 | G2: 3186.64 | H2: PayPal | I2: Shipped | J2: South Patrickshire | K2: =Row_Data!$F2*Row_Data!$G2 -> 12746.56 | L2: =TEXT(Row_Data!$B2,"MMM "&"YYY") -> Jan 2025
A3: 1204 | B3: 45664 | C3: dyoung@stokes.com | D3: Speaker | E3: Accessories | F3: 3 | G3: 3918.42 | H3: Credit Card | I3: Cancelled | J3: New Crystal | K3: =Row_Data!$F3*Row_Data!$G3 -> 11755.26 | L3: =TEXT(Row_Data!$B3,"MMM "&"YYY") -> Jan 2025
A4: 6212 | B4: 45665 | C4: lee69@hotmail.com | D4: Keyboard | E4: Accessories | F4: 2 | G4: 2898.21 | H4: Credit Card | I4: Shipped | J4: West Destiny | K4: =Row_Data!$F4*Row_Data!$G4 -> 5796.42 | L4: =TEXT(Row_Data!$B4,"MMM "&"YYY") -> Jan 2025
A5: 8491 | B5: 45665 | C5: paul14@hamilton.biz | D5: Keyboard | E5: Accessories | F5: 2 | G5: 963.34 | H5: PayPal | I5: Cancelled | J5: Stacieton | K5: =Row_Data!$F5*Row_Data!$G5 -> 1926.68 | L5: =TEXT(Row_Data!$B5,"MMM "&"YYY") -> Jan 2025
A6: 3603 | B6: 45667 | C6: eric77@gmail.com | D6: USB Cable | E6: Accessories | F6: 5 | G6: 4340.71 | H6: Cash | I6: Cancelled | J6: Edwinberg | K6: =Row_Data!$F6*Row_Data!$G6 -> 21703.55 | L6: =TEXT(Row_Data!$B6,"MMM "&"YYY") -> Jan 2025
A7: 3068 | B7: 45667 | C7: ejones@calderon.com | D7: USB Cable | E7: Office | F7: 2 | G7: 988.2 | H7: Cash | I7: Shipped | J7: West Daniel | K7: =Row_Data!$F7*Row_Data!$G7 -> 1976.4 | L7: =TEXT(Row_Data!$B7,"MMM "&"YYY") -> Jan 2025
A8: 2933 | B8: 45668 | C8: wonghayley@hotmail.com | D8: Charger | E8: Accessories | F8: 1 | G8: 1619.68 | H8: Credit Card | I8: Cancelled | J8: North Ruth | K8: =Row_Data!$F8*Row_Data!$G8 -> 1619.68 | L8: =TEXT(Row_Data!$B8,"MMM "&"YYY") -> Jan 2025
A9: 4798 | B9: 45669 | C9: kelly28@gmail.com | D9: Charger | E9: Office | F9: 3 | G9: 931.37 | H9: Cash | I9: Shipped | J9: Lake David | K9: =Row_Data!$F9*Row_Data!$G9 -> 2794.11 | L9: =TEXT(Row_Data!$B9,"MMM "&"YYY") -> Jan 2025
A10: 6888 | B10: 45669 | C10: taylor42@rogers-carpenter.biz | D10: Webcam | E10: Office | F10: 3 | G10: 1065.6 | H10: PayPal | I10: Cancelled | J10: Michaelstad | K10: =Row_Data!$F10*Row_Data!$G10 -> 3196.8 | L10: =TEXT(Row_Data!$B10,"MMM "&"YYY") -> Jan 2025
A11: 7489 | B11: 45670 | C11: aaronsmith@yahoo.com | D11: Headphones | E11: Office | F11: 3 | G11: 4467.71 | H11: Credit Card | I11: Shipped | J11: Jeffreyshire | K11: =Row_Data!$F11*Row_Data!$G11 -> 13403.13 | L11: =TEXT(Row_Data!$B11,"MMM "&"YYY") -> Jan 2025
A12: 3485 | B12: 45670 | C12: debbiebeltran@yahoo.com | D12: Headphones | E12: Office | F12: 1 | G12: 478.66 | H12: Credit Card | I12: Cancelled | J12: Hardinville | K12: =Row_Data!$F12*Row_Data!$G12 -> 478.66 | L12: =TEXT(Row_Data!$B12,"MMM "&"YYY") -> Jan 2025
A13: 4327 | B13: 45671 | C13: krobertson@nelson.biz | D13: Monitor | E13: Electronics | F13: 3 | G13: 1682.37 | H13: Cash | I13: Cancelled | J13: Pollardborough | K13: =Row_Data!$F13*Row_Data!$G13 -> 5047.11 | L13: =TEXT(Row_Data!$B13,"MMM "&"YYY") -> Jan 2025
... A321: 8892 | B321: 45846 | C321: chad26@hurley.com | D321: Charger | E321: Electronics | F321: 2 | G321: 3853.02 | H321: Credit Card | I321: Shipped | J321: Hudsonhaven | K321: =Row_Data!$F321*Row_Data!$G321 -> 7706.04 | L321: =TEXT(Row_Data!$B321,"MMM "&"YYY") -> Jul 2025

Sheet SUM
C1: Month | D1: Sales (SUMIFS) | E1: Sales (SUMIF) | H1: Month | I1: Sales (Avg If) | J1: Sales (Avg Ifs)
C2: 45658 | D2: =SUMIF(Row_Data!L:L,SUM!C2,Row_Data!K:K) -> 384199.1 | E2: =SUMIFS(Row_Data!K:K,Row_Data!L:L,SUM!C2) -> 384199.1 | H2: Jan 2025 | I2: =AVERAGEIF(Row_Data!L:L,SUM!H2,Row_Data!K:K) -> 7114.7981 | J2: =AVERAGEIFS(Row_Data!K:K,Row_Data!L:L,SUM!H2) -> 7114.7981
C3: Feb 2025 | D3: =SUMIF(Row_Data!L:L,SUM!C3,Row_Data!K:K) -> 446434.09 | E3: =SUMIFS(Row_Data!K:K,Row_Data!L:L,SUM!C3) -> 446434.09 | H3: Feb 2025 | I3: =AVERAGEIF(Row_Data!L:L,SUM!H3,Row_Data!K:K) -> 8116.9835 | J3: =AVERAGEIFS(Row_Data!K:K,Row_Data!L:L,SUM!H3) -> 8116.9835
C4: Mar 2025 | D4: =SUMIF(Row_Data!L:L,SUM!C4,Row_Data!K:K) -> 395126.42 | E4: =SUMIFS(Row_Data!K:K,Row_Data!L:L,SUM!C4) -> 395126.42 | H4: Mar 2025 | I4: =AVERAGEIF(Row_Data!L:L,SUM!H4,Row_Data!K:K) -> 6932.0425 | J4: =AVERAGEIFS(Row_Data!K:K,Row_Data!L:L,SUM!H4) -> 6932.0425
C5: Apr 2025 | D5: =SUMIF(Row_Data!L:L,SUM!C5,Row_Data!K:K) -> 224733.48 | E5: =SUMIFS(Row_Data!K:K,Row_Data!L:L,SUM!C5) -> 224733.48 | H5: Apr 2025 | I5: =AVERAGEIF(Row_Data!L:L,SUM!H5,Row_Data!K:K) -> 6810.1055 | J5: =AVERAGEIFS(Row_Data!K:K,Row_Data!L:L,SUM!H5) -> 6810.1055
C6: May 2025 | D6: =SUMIF(Row_Data!L:L,SUM!C6,Row_Data!K:K) -> 455498.49 | E6: =SUMIFS(Row_Data!K:K,Row_Data!L:L,SUM!C6) -> 455498.49 | H6: May 2025 | I6: =AVERAGEIF(Row_Data!L:L,SUM!H6,Row_Data!K:K) -> 7853.4222 | J6: =AVERAGEIFS(Row_Data!K:K,Row_Data!L:L,SUM!H6) -> 7853.4222
C7: Jun 2025 | D7: =SUMIF(Row_Data!L:L,SUM!C7,Row_Data!K:K) -> 371657.65 | E7: =SUMIFS(Row_Data!K:K,Row_Data!L:L,SUM!C7) -> 371657.65 | H7: Jun 2025 | I7: =AVERAGEIF(Row_Data!L:L,SUM!H7,Row_Data!K:K) -> 8079.5141 | J7: =AVERAGEIFS(Row_Data!K:K,Row_Data!L:L,SUM!H7) -> 8079.5141
C8: Jul 2025 | D8: =SUMIF(Row_Data!L:L,SUM!C8,Row_Data!K:K) -> 149662.97 | E8: =SUMIFS(Row_Data!K:K,Row_Data!L:L,SUM!C8) -> 149662.97 | H8: Jul 2025 | I8: =AVERAGEIF(Row_Data!L:L,SUM!H8,Row_Data!K:K) -> 8803.7041 | J8: =AVERAGEIFS(Row_Data!K:K,Row_Data!L:L,SUM!H8) -> 8803.7041

Sheet 1
A1: sequence &count
A2: Serial | B2: HRID | C2: Names | D2: Gender | E2: Destination | H2: Use a formula to count the number of people in the list
A3: {=_xlfn.SEQUENCE(COUNT(B3:B21),,1,1)} -> 1 | B3: 2469 | C3: Mohamed | D3: Male | E3: =COUNTBLANK(I13:K62) -> 150
A4: 2 | B4: 2036 | C4: Christine | D4: Female | E4: =COUNTIF([1]!Table1[Account],"Movefix") -> #REF!
A5: 3 | B5: 3456 | C5: Shimaa | D5: Female | E5: =COUNTIF([1]!Table1[Gender],"Female") -> #REF!
A6: 4 | B6: 1011 | C6: Chris | D6: Male | E6: =COUNTIF(K13:K62,"No") -> 0 | I6: Number of people
A7: 5 | B7: 331 | C7: Nermine | D7: Female | E7: =COUNTIFS(G12:G62,">=70%",G12:G62,"<=90%") -> 0 | H7: Numbers | I7: =COUNT(B3:B21) -> 19
A8: 6 | B8: 828 | C8: Mina | D8: Male | E8: Lebanon | H8: Names | I8: =COUNTA(C3:C21) -> 19
A9: 7 | B9: 10111 | C9: Maram | D9: Female | E9: Sudan
A10: 8 | B10: 6387 | C10: Mayar | D10: Female | E10: Lebanon
A11: 9 | B11: 9292 | C11: Hossam | D11: Male | E11: Lebanon
A12: 10 | B12: 3723 | C12: Heba | D12: Female | E12: 6th of October
A13: 11 | B13: 727 | C13: Tamer | D13: Male | E13: Sudan
A14: 12 | B14: 939 | C14: Hany | D14: Male | E14: Al Batal Ahmad
A15: 13 | B15: 847 | C15: Rasha | D15: Female | E15: Sudan
A16: 14 | B16: 8483 | C16: Lama | D16: Female | E16: 6th of October
A17: 15 | B17: 988 | C17: Marihan | D17: Female | E17: Lebanon
A18: 16 | B18: 67 | C18: Fouad | D18: Male | E18: Lebanon
A19: 17 | B19: 5236.6667 | C19: Philip | D19: Male | E19: Agouza
A20: 18 | B20: 9444.6667 | C20: Mona | D20: Female | E20: Agouza
A21: 19 | B21: 13652.667 | C21: Hassan | D21: Male | E21: Agouza

Sheet 2
A1: Serial | B1: HRID | C1: Names | D1: Gender | E1: Destination | H1: Use a formula to count the number of blank Cells
B2: 2469 | C2: Mohamed | D2: Male | E2: Sudan
B3: 2036 | C3: Christine | D3: Female | E3: Al Batal Ahmad
B4: 3456 | C4: Shimaa | D4: Female | H4: Number of Blank Cells
B5: 1011 | C5: Chris | D5: Male | E5: Sudan | H5: =COUNTBLANK(B1:E20) -> 4
B6: 331 | C6: Nermine | E6: Sudan
B7: 828 | C7: Mina | D7: Male | E7: Lebanon
B8: 10111 | C8: Maram | D8: Female | E8: Sudan
B9: 6387 | C9: Mayar | D9: Female | E9: Lebanon
B10: 9292 | C10: Hossam | D10: Male | E10: Lebanon
B11: 3723 | C11: Heba | D11: Female | E11: 6th of October
B12: 727 | C12: Tamer | D12: Male | E12: Sudan
B13: 939 | C13: Hany | D13: Male | E13: Al Batal Ahmad
C14: Rasha | D14: Female | E14: Sudan
B15: 8483 | C15: Lama | D15: Female | E15: 6th of October
B16: 988 | C16: Marihan | D16: Female | E16: Lebanon
B17: 67 | C17: Fouad | D17: Male | E17: Lebanon
B18: 5236.6667 | C18: Philip | E18: Agouza
B19: 9444.6667 | C19: Mona | D19: Female | E19: Agouza
B20: 13652.667 | C20: Hassan | D20: Male | E20: Agouza

Sheet 3
A1: Serial | B1: HRID | C1: Names | D1: Gender | E1: Destination
A2: {=_xlfn.SEQUENCE(COUNT(B:B),,1,1)} -> 1 | B2: 2469 | C2: Mohamed | D2: Male | E2: 6th of October
A3: 2 | B3: 2036 | C3: Christine | D3: Female | E3: 6th of October | G3: Male | H3: Female | J3: Count the number of males and females
A4: 3 | B4: 3456 | C4: Shimaa | D4: Female | E4: Lebanon | G4: =COUNTIF($D:$D,G3) -> 9 | H4: =COUNTIF($D:$D,H3) -> 11
A5: 4 | B5: 1011 | C5: Chris | D5: Male | E5: Lebanon
A6: 5 | B6: 331 | C6: Nermine | D6: Female | E6: Lebanon
A7: 6 | B7: 828 | C7: Mina | D7: Male | E7: Lebanon
A8: 7 | B8: 10111 | C8: Maram | D8: Female | E8: Sudan
A9: 8 | B9: 6387 | C9: Mayar | D9: Female | E9: Lebanon
A10: 9 | B10: 9292 | C10: Hossam | D10: Male | E10: Lebanon
A11: 10 | B11: 3723 | C11: Heba | D11: Female | E11: 6th of October
A12: 11 | B12: 727 | C12: Tamer | D12: Male | E12: Sudan
A13: 12 | B13: 939 | C13: Hany | D13: Male | E13: Al Batal Ahmad
A14: 13 | B14: 847 | C14: Rasha | D14: Female | E14: Sudan
A15: 14 | B15: 8483 | C15: Lama | D15: Female | E15: 6th of October
A16: 15 | B16: 988 | C16: Marihan | D16: Female | E16: Lebanon
... A21: 20 | B21: 2036 | C21: Christine | D21: Female | E21: Aguza

Sheet 4
A1: Serial | B1: HRID | C1: Names | D1: Gender | E1: Destination | F1: Location | G1: loc
B2: 2469 | C2: Mohamed | D2: Male | E2: =COUNTBLANK(J12:L61) -> 150 | F2: 6th of October Giza | G2: =RIGHT(F2,FIND(" ",F2)) -> Giza | I2: Count all Student
B3: 2036 | C3: Christine | D3: Female | E3: =COUNTIF([1]!Table1[Account],"Movefix") -> #REF! | F3: Tahrir Cairo | G3: =RIGHT(F3,FIND(" ",F3)) -> r Cairo
B4: 3456 | C4: Shimaa | D4: Female | E4: =COUNTIF([1]!Table1[Gender],"Female") -> #REF! | F4: Sphinx Giza | G4: =RIGHT(F4,FIND(" ",F4)) -> nx Giza
B5: 1011 | C5: Chris | D5: Male | E5: =COUNTIF(L12:L61,"No") -> 0 | F5: 6th of October Giza | G5: =RIGHT(F5,FIND(" ",F5)) -> Giza
B6: 331 | C6: Nermine | D6: Female | E6: =COUNTIFS(H11:H61,">=70%",H11:H61,"<=90%") -> 0 | F6: Tahrir Cairo | G6: =RIGHT(F6,FIND(" ",F6)) -> r Cairo
B7: 828 | C7: Mina | D7: Male | E7: Lebanon | F7: Lebanon Giza | G7: =RIGHT(F7,FIND(" ",F7)) -> non Giza
B8: 10111 | C8: Maram | D8: Female | E8: Sudan | F8: Sudan Giza | G8: =RIGHT(F8,FIND(" ",F8)) -> n Giza
B9: 6387 | C9: Mayar | D9: Female | E9: Lebanon | F9: Lebanon Giza | G9: =RIGHT(F9,FIND(" ",F9)) -> non Giza | I9: Count students living in Giza
B10: 9292 | C10: Hossam | D10: Male | E10: Lebanon | F10: Lebanon Giza | G10: =RIGHT(F10,FIND(" ",F10)) -> non Giza | I10: =COUNTIF(F2:F20,"*Giza*") -> 17
B11: 3723 | C11: Heba | D11: Female | E11: 6th of October | F11: 6th of October Giza | G11: =RIGHT(F11,FIND(" ",F11)) -> Giza
B12: 727 | C12: Tamer | D12: Male | E12: Sudan | F12: Sudan Giza | G12: =RIGHT(F12,FIND(" ",F12)) -> n Giza | I12: Count students living in Cairo
B13: 939 | C13: Hany | D13: Male | E13: Al Batal Ahmad | F13: Al Batal Ahmad Giza | G13: =RIGHT(F13,FIND(" ",F13)) -> iza | I13: =COUNTIF(F2:F20,"*Cairo*") -> 2
B14: 847 | C14: Rasha | D14: Female | E14: Sudan | F14: Sudan Giza | G14: =RIGHT(F14,FIND(" ",F14)) -> n Giza
B15: 8483 | C15: Lama | D15: Female | E15: 6th of October | F15: 6th of October Giza | G15: =RIGHT(F15,FIND(" ",F15)) -> Giza
B16: 988 | C16: Marihan | D16: Female | E16: Lebanon | F16: Lebanon Giza | G16: =RIGHT(F16,FIND(" ",F16)) -> non Giza
B17: 67 | C17: Fouad | D17: Male | E17: Lebanon | F17: Lebanon Giza | G17: =RIGHT(F17,FIND(" ",F17)) -> non Giza
B18: 5236.6667 | C18: Philip | D18: Male | E18: Agouza | F18: Agouza Giza | G18: =RIGHT(F18,FIND(" ",F18)) -> za Giza
B19: 9444.6667 | C19: Mona | D19: Female | E19: Agouza | F19: Agouza Giza | G19: =RIGHT(F19,FIND(" ",F19)) -> za Giza
B20: 13652.667 | C20: Hassan | D20: Male | E20: Agouza | F20: Agouza Giza | G20: =RIGHT(F20,FIND(" ",F20)) -> za Giza

Sheet 5
B2: Calculate the number of | D2: How many Documents with unknown status (empty cells) | E2: Question 8 | F2: =COUNTBLANK(B11:K61) -> 7
D3: Number of agents in Movefix only | E3: Question 9 | F3: =COUNTIF(Table1[Account],$G$3) -> 10 | G3: Movefix
D4: Females Only | E4: Question 10 | F4: =COUNTIF(Table1[Gender],$G$4) -> 30 | G4: Female
D5: Males who did not provide the military certificate | E5: Question 11 | F5: =COUNTIFS(Table1[Gender],$G$5,$K$12:$K$61,"No") -> 4 | G5: Male
D6: Agents with QA% score between 70%, and 90% | E6: Question 12 | F6: =COUNTIFS(G12:G61,">=70%",G12:G61,"<=90%") -> 10
D7: Including 70% and 90%
I9: Document Available
A11: Serial | B11: HRID | C11: Name | D11: Account | E11: Phone Number | F11: Gender | G11: QA% | H11: Abs | I11: Birth Certification | J11: Criminal Record | K11: Military Certificate
B12: 9399 | C12: Williams Dupont | D12: Movefix | E12: 1207268750 | F12: Male | G12: 0.61 | H12: 0.08 | J12: Yes | K12: No
B13: 5394 | C13: Deanne Chaidez | D13: Sail Quodax | E13: 1020230753 | F13: Female | G13: 0.13 | H13: 0.03 | I13: Yes | J13: Yes | K13: NA
B14: 2164 | C14: Khadijah Mateer | D14: Lexsoft | E14: 1211823573 | F14: Female | G14: 0.58 | H14: 0.03 | I14: Yes | J14: Yes | K14: NA
B15: 6698 | C15: Chae Castelli | D15: Anron | E15: 1042264784 | F15: Female | G15: 0.49 | H15: 0.05 | I15: Yes | J15: Yes | K15: NA
B16: 685 | C16: Fredric Alden | D16: Ranktough | E16: 1229475771 | F16: Male | G16: 0.02 | H16: 0.02 | I16: Yes | J16: No | K16: Yes
B17: 8655 | C17: Keiko Sweitzer | D17: Lexsoft | E17: 1029843309 | F17: Female | G17: 0.14 | H17: 0.03 | I17: No | J17: Yes | K17: NA
B18: 8083 | C18: Lupe Huntley | D18: Sail Quodax | E18: 1228662133 | F18: Male | G18: 0.93 | H18: 0.01 | I18: Yes | J18: Yes | K18: Yes
B19: 9152 | C19: Annetta Mccotter | D19: Sail Quodax | E19: 1095275788 | F19: Female | G19: 0.9 | H19: 0.01 | I19: No | J19: Yes | K19: NA
B20: 1729 | C20: Violet Krejci | D20: Lexsoft | E20: 1171220560 | F20: Female | G20: 0.5 | H20: 0.03 | I20: Yes | J20: Yes | K20: NA
B21: 651 | C21: Marcelle Seip | D21: Ranktough | E21: 1209584210 | F21: Female | G21: 0.73 | H21: 0.08 | I21: Yes | J21: No | K21: NA
B22: 745 | C22: Nova Flanary | D22: Ranktough | E22: 1159560103 | F22: Female | G22: 0.67 | H22: 0.02 | I22: Yes | J22: No | K22: NA
B23: 867 | C23: Fred Chism | D23: Movefix | E23: 1179633564 | F23: Male | G23: 0.88 | H23: 0.05 | I23: Yes | J23: Yes | K23: Yes
B24: 7893 | C24: Tora Brister | D24: Movefix | E24: 1095089063 | F24: Female | G24: 0.04 | H24: 0.01 | I24: Yes | J24: Yes | K24: NA
... B32: 8991 | C32: Ismael Borman | D32: Anron | E32: 1203026420 | F32: Male | G32: 0.37 | H32: 0.03 | I32: Yes | J32: Yes | K32: No
B33: 2165 | C33: Clifton Brouse | D33: Lexsoft | E33: 1041891625 | F33: Male | G33: 0.26 | H33: 0.01 | J33: Yes | K33: Yes
B34: 3719 | C34: Lady Mickey | D34: Anron | E34: 1241242953 | F34: Female | G34: 0.91 | H34: 0.08 | I34: Yes | J34: Yes | K34: NA
B35: 3389 | C35: Ethelyn Marrone | D35: Anron | E35: 1109407690 | F35: Female | G35: 0.91 | H35: 0.08 | I35: Yes | J35: Yes | K35: NA
B36: 6080 | C36: Benita Maciel | D36: Anron | E36: 1175219344 | F36: Female | G36: 0.08 | H36: 0.01 | I36: Yes | J36: Yes | K36: NA
B37: 8889 | C37: Consuelo Gaccione | D37: Sail Quodax | E37: 1049795052 | F37: Female | G37: 0.22 | H37: 0.04 | I37: Yes | J37: Yes | K37: NA
B38: 4559 | C38: Marty Corry | D38: Movefix | E38: 1227262302 | F38: Male | G38: 0.94 | H38: 0 | I38: Yes | J38: No | K38: No
B39: 4384 | C39: Reginia Estrada | D39: Ranktough | E39: 1039512242 | F39: Female | G39: 0.32 | H39: 0.05 | I39: Yes | J39: Yes | K39: NA
B40: 9587 | C40: Kim Okelly | D40: Lexsoft | E40: 1161862060 | F40: Male | G40: 0.03 | H40: 0.03 | I40: No | J40: Yes | K40: Yes
B41: 9669 | C41: Morton Zoll | D41: Movefix | E41: 1069679084 | F41: Male | G41: 0.73 | H41: 0.06 | I41: Yes | J41: Yes | K41: Yes
B42: 5458 | C42: Jazmin Hudgens | D42: Ranktough | E42: 1023316861 | F42: Female | G42: 0.63 | H42: 0.01 | I42: Yes | J42: Yes | K42: NA
B43: 9907 | C43: Elliott Dorfman | D43: Sail Quodax | E43: 1069784062 | F43: Male | G43: 0.2 | H43: 0.09 | J43: Yes | K43: Yes
B44: 7793 | C44: Gisele Calmes | D44: Anron | E44: 1162181595 | F44: Female | G44: 0.45 | H44: 0.08 | I44: Yes | J44: Yes | K44: NA
B45: 6962 | C45: Jessia Hocking | D45: Sail Quodax | E45: 1208553470 | F45: Female | G45: 0.62 | H45: 0.02 | I45: Yes | J45: No | K45: NA
B46: 7108 | C46: Sierra Neeson | D46: Anron | E46: 1219222614 | F46: Female | G46: 0.91 | H46: 0.06 | I46: Yes | J46: Yes | K46: NA
B47: 4095 | C47: Kylie Walk | D47: Ranktough | E47: 1200209715 | F47: Female | G47: 0.66 | H47: 0.02 | I47: Yes | J47: Yes | K47: NA
B48: 8385 | C48: Robbin Foran | D48: Ranktough | E48: 1170109748 | F48: Female | G48: 0.6 | H48: 0.09 | I48: No | J48: No | K48: NA
B49: 2248 | C49: Ernie Overholt | D49: Lexsoft | E49: 1061618598 | F49: Male | G49: 0.62 | H49: 0.08 | I49: Yes | J49: Yes | K49: Yes
B50: 9927 | C50: Alec Kinkade | D50: Movefix | E50: 1043602094 | F50: Male | G50: 0.23 | H50: 0.04 | I50: Yes | J50: Yes | K50: Yes
...

Sheet 6
A1: Student Name | B1: Address | C1: Score
A2: Ayman Magdy | B2: Maadi, Cairo | C2: 0.85 | H2: Count students living in Maadi
A3: Ahmed Hassan | B3: Nasr City, Cairo | C3: 0.72 | H3: =COUNTIF(B2:B21,"*Maadi*") -> 6
A4: Rania Adel | B4: Alexandria Downtown | C4: 0.9
A5: Mohamed Ali | B5: Maadi, Cairo | C5: 0.67 | H5: Count students whose name contains Ayman
A6: Sara Ayman | B6: Nasr City, Cairo | C6: 0.75 | H6: =COUNTIF(A2:A21,"*Ayman*") -> 4
A7: Youssef Ibrahim | B7: Mansoura, Dakahlia | C7: 0.88
A8: Mariam Mostafa | B8: Maadi, Cairo | C8: 0.95 | H8: Count students whose address contains Cairo
A9: Hossam Tarek | B9: Helwan, Cairo | C9: 0.6 | H9: =COUNTIF(B2:B21,"*Cairo*") -> 13
A10: Mona Ahmed | B10: Nasr City, Cairo | C10: 0.8
A11: Farah Mohamed | B11: Alexandria Corniche | C11: 0.78 | H11: Count students whose name starts with “M”
A12: Islam Magdy | B12: Maadi, Cairo | C12: 0.82 | H12: =COUNTIF(A2:A21,"M*") -> 4
A13: Laila Hassan | B13: Nasr City, Cairo | C13: 0.69
A14: Karim Adel | B14: Mansoura, Dakahlia | C14: 0.74
A15: Hany Samir | B15: Alexandria Smouha | C15: 0.93
A16: Rawan Ayman | B16: Maadi, Cairo | C16: 0.7
A17: Salma Nabil | B17: Helwan, Cairo | C17: 0.64
A18: Tamer Fathi | B18: Nasr City, Cairo | C18: 0.87
A19: Mariam Hassan | B19: Maadi, Cairo | C19: 0.91
A20: Omar Khaled | B20: Alexandria Downtown | C20: 0.89
A21: Ayman Adel | B21: Mansoura, Dakahlia | C21: 0.77

Sheet 7
A1: Serial | B1: HRID | C1: Name | D1: Account | E1: Gender | F1: QA% | G1: Abs | H1: Bonus in EGP | I1: Overnight allowance | J1: Total
A2: 1 | B2: 9399 | C2: Williams Dupont | D2: Movefix | E2: Male | F2: 0.61 | G2: 0.08 | H2: 100 | I2: 100 | J2: =SUM(H2:I2) -> 200 | N2: Account | O2: Answer
A3: 2 | B3: 5394 | C3: Deanne Chaidez | D3: Sail Quodax | E3: Female | F3: 0.13 | G3: 0.03 | H3: 0 | I3: 0 | J3: =SUM(H3:I3) -> 0 | N3: Movefix | O3: =COUNTIF($D$2:$D$51,$N3) -> 10
A4: 3 | B4: 2164 | C4: Khadijah Mateer | D4: Lexsoft | E4: Female | F4: 0.58 | G4: 0.03 | H4: 100 | I4: 50 | J4: =SUM(H4:I4) -> 150 | N4: Sail Quodax | O4: =COUNTIF($D$2:$D$51,$N4) -> 10
A5: 4 | B5: 6698 | C5: Chae Castelli | D5: Anron | E5: Female | F5: 0.49 | G5: 0.05 | H5: 0 | I5: 0 | J5: =SUM(H5:I5) -> 0 | N5: Lexsoft | O5: =COUNTIF($D$2:$D$51,$N5) -> 10
A6: 5 | B6: 685 | C6: Fredric Alden | D6: Ranktough | E6: Male | F6: 0.02 | G6: 0.02 | H6: 0 | I6: 100 | J6: =SUM(H6:I6) -> 100 | N6: Anron | O6: =COUNTIF($D$2:$D$51,$N6) -> 10
A7: 6 | B7: 8655 | C7: Keiko Sweitzer | D7: Lexsoft | E7: Female | F7: 0.14 | G7: 0.03 | H7: 0 | I7: 0 | J7: =SUM(H7:I7) -> 0 | N7: Ranktough | O7: =COUNTIF($D$2:$D$51,$N7) -> 10
A8: 7 | B8: 8083 | C8: Lupe Huntley | D8: Sail Quodax | E8: Male | F8: 0.93 | G8: 0.01 | H8: 1000 | I8: 100 | J8: =SUM(H8:I8) -> 1100
A9: 8 | B9: 9152 | C9: Annetta Mccotter | D9: Sail Quodax | E9: Female | F9: 0.9 | G9: 0.01 | H9: 1000 | I9: 200 | J9: =SUM(H9:I9) -> 1200
A10: 9 | B10: 1729 | C10: Violet Krejci | D10: Lexsoft | E10: Female | F10: 0.5 | G10: 0.03 | H10: 0 | I10: 100 | J10: =SUM(H10:I10) -> 100 | N10: Gender | O10: Answer
A11: 10 | B11: 651 | C11: Marcelle Seip | D11: Ranktough | E11: Female | F11: 0.73 | G11: 0.08 | H11: 100 | I11: 0 | J11: =SUM(H11:I11) -> 100 | N11: Male | O11: =COUNTIF(E2:E51,$N11) -> 20
A12: 11 | B12: 745 | C12: Nova Flanary | D12: Ranktough | E12: Female | F12: 0.67 | G12: 0.02 | H12: 100 | I12: 0 | J12: =SUM(H12:I12) -> 100 | N12: Female | O12: =COUNTIF(E3:E52,$N12) -> 30
A13: 12 | B13: 867 | C13: Fred Chism | D13: Movefix | E13: Male | F13: 0.88 | G13: 0.05 | H13: 500 | I13: 100 | J13: =SUM(H13:I13) -> 600
A14: 13 | B14: 7893 | C14: Tora Brister | D14: Movefix | E14: Female | F14: 0.04 | G14: 0.01 | H14: 0 | I14: 0 | J14: =SUM(H14:I14) -> 0
A15: 14 | B15: 9607 | C15: Lincoln Gassett | D15: Anron | E15: Male | F15: 0.32 | G15: 0.06 | H15: 0 | I15: 100 | J15: =SUM(H15:I15) -> 100
A16: 15 | B16: 9784 | C16: Dee Peppers | D16: Ranktough | E16: Male | F16: 0.84 | G16: 0.08 | H16: 500 | I16: 100 | J16: =SUM(H16:I16) -> 600
A17: 16 | B17: 4161 | C17: Daryl Hedley | D17: Sail Quodax | E17: Male | F17: 0.69 | G17: 0.07 | H17: 100 | I17: 100 | J17: =SUM(H17:I17) -> 200
A18: 17 | B18: 7093 | C18: Tiny Jarrard | D18: Lexsoft | E18: Female | F18: 0.85 | G18: 0.04 | H18: 500 | I18: 0 | J18: =SUM(H18:I18) -> 500
A19: 18 | B19: 3697 | C19: Teena Elliff | D19: Lexsoft | E19: Female | F19: 0.89 | G19: 0 | H19: 500 | I19: 100 | J19: =SUM(H19:I19) -> 600
A20: 19 | B20: 5433 | C20: Starla Walcott | D20: Lexsoft | E20: Female | F20: 0.14 | G20: 0.07 | H20: 0 | I20: 0 | J20: =SUM(H20:I20) -> 0
A21: 20 | B21: 4400 | C21: Edmond Taliaferro | D21: Movefix | E21: Male | F21: 0.41 | G21: 0.05 | H21: 1000 | I21: 100 | J21: =SUM(H21:I21) -> 1100
A22: 21 | B22: 8991 | C22: Ismael Borman | D22: Anron | E22: Male | F22: 0.37 | G22: 0.03 | H22: 0 | I22: 100 | J22: =SUM(H22:I22) -> 100
A23: 22 | B23: 2165 | C23: Clifton Brouse | D23: Lexsoft | E23: Male | F23: 0.26 | G23: 0.01 | H23: 100 | I23: 100 | J23: =SUM(H23:I23) -> 200
A24: 23 | B24: 3719 | C24: Lady Mickey | D24: Anron | E24: Female | F24: 0.91 | G24: 0.08 | H24: 1000 | I24: 0 | J24: =SUM(H24:I24) -> 1000
... A51: 50 | B51: 9101 | C51: Larita Gaudin | D51: Anron | E51: Female | F51: 0.58 | G51: 0.08 | H51: 0 | I51: 0 | J51: =SUM(H51:I51) -> 0

Sheet CST
A1: Customer Name | B1: Customer Email | C1: City
A2: Andres Holloway MD | B2: sheila94@hotmail.com | C2: South Patrickshire
A3: Nathan Garcia | B3: sjenkins@gmail.com | C3: New Crystal
A4: Joshua Vincent | B4: dfitzpatrick@short.com | C4: West Destiny
A5: Steven Foster | B5: wjones@bell.net | C5: Stacieton
A6: Lauren Rose | B6: iflores@aguilar.com | C6: Edwinberg
A7: Kelly Greene | B7: catherineclark@hotmail.com | C7: West Daniel
A8: Dawn Munoz | B8: craig46@taylor.info | C8: North Ruth
A9: Eric Hopkins | B9: krush@hotmail.com | C9: Lake David
A10: Ana Davis | B10: scottcolin@gmail.com | C10: Michaelstad
A11: Rachael Wheeler | B11: joshuapowers@sawyer-reed.net | C11: Jeffreyshire
A12: Michael Williams | B12: timothynewman@hotmail.com | C12: Hardinville
... A321: Erin Thompson | B321: scott08@miller.com | C321: Hudsonhaven
